Workbook

Sheet فقرة 50
A1: الصندوق الوطني | T1: جدول الاشتراكات المتوجبة والناتجة عن الفقرة 50 لسنة
A2: للضمان الاجتماعي | U2: والمتوجب دفعها حتى تاريخ | AA2: 31 | AE2: 12 | AF2: 2025
A5: حقل مخصص لأرباب العمل | T5: حقل مخصص للصندوق
AR6: الصفحة
AD7: طريقة دفع الاشتراكات | AL7: المدة | AX7: مؤسسة | BB7: شهرية
B9: اسم المؤسسة : | AR9: 1 | BB9: فصلية
AE10: شك | AH10: 3
AE12: تحويل مصرفي | AH12: 2
N14: 2 | O14: 2 | AE14: نقدًا | AH14: 1
B15: رقم المؤسسة :
AE16: غير مدفوع | AH16: 0
AL17: فترة | AO17: سنة
B20: فرع | C20: عدد الاجراء | F20: الاجور ولواحقها | N20: المعدل | P20: الاشتراكات المستحقة | U20: الاشتراكات المدفوعة | AD20: زيادات التأخير
X21: الرمز | AD21: المتوجب | AL21: المدفوع | AZ21: الفرع
B22: المرض والامومة | N22: 0.11
Y25: 1 | Z25: 0 | AU25: 7 | AV25: 0 | AW25: 0
Y27: 1 | Z27: 1 | AU27: 7 | AV27: 7 | AW27: 7 | BE27: 3
B30: تعويض نهاية الخدمة | N30: 8.5%
Y33: 1 | Z33: 0 | AU33: 7 | AV33: 0 | AW33: 0
Y35: 1 | Z35: 1 | AU35: 7 | AV35: 7 | AW35: 7 | BE35: 1
B38: التعويضات العائلية | N38: 0.06
AU39: 7 | AV39: 7 | AW39: 7
AU41: 7 | AV41: 7 | AW41: 7
Y43: 1 | Z43: 0 | AU43: 7 | AV43: 7 | AW43: 7 | BE43: 2
F44: مجموع الاشتراكات المستحقة
Y46: 1 | Z46: 1
F47: التعويضات العائلية المدفوعة
A49: الزيادة المتوجبة على الصندوق/الباقي المتوجب للصندوق
BA51: المصفي | BB51: ………...………
B53: ــــــــــــــــــــــــــــ في ـــــــــــــــــــــــ 20 | P53: توقيع وختم رب العمل | BA53: المراقب | BB53: ………...………
B54: ملاحظة هامة: | AF54: مجموع المبالغ المدفوعة | BA54: المحاسب | BB54: ………...………
B55: يتوجب اعادة هذا الجدول مع جدول التصريح الاسمي السنوي المرفق
BB56: cnss 351

Sheet التسوية
A1: الصندوق الوطني | S1: جدول الاشتراكات المتوجبة والناتجة عن التصريح الإسمي السنوي لعام
A2: للضمان الاجتماعي | T2: والمتوجب دفعها حتى تاريخ | Z2: 31 | AD2: 12 | AE2: 2025
S5: حقل مخصص للصندوق
AQ6: الصفحة
AC7: طريقة دفع الاشتراكات | AK7: المدة | AW7: مؤسسة | BA7: شهرية
A9: اسم المؤسسة : | AQ9: 1 | BA9: فصلية
AD10: شك | AG10: 3
AD12: تحويل مصرفي | AG12: 2
M14: 2 | N14: 2 | AD14: نقدًا | AG14: 1
A15: رقم المؤسسة :
AD16: غير مدفوع | AG16: 0
AK17: فترة | AN17: سنة
A20: فرع | B20: عدد الاجراء | E20: الاجور ولواحقها | M20: المعدل | O20: الاشتراكات المستحقة | T20: الاشتراكات المدفوعة | AC20: زيادات التأخير
W21: الرمز | AC21: المتوجب | AK21: المدفوع | AY21: الفرع
A22: المرض والامومة | M22: 0.11
X25: 1 | Y25: 0 | AT25: 7 | AU25: 0 | AV25: 0
X27: 1 | Y27: 1 | AT27: 7 | AU27: 7 | AV27: 7 | BD27: 3
A30: تعويض نهاية الخدمة | M30: 8.5%
X33: 1 | Y33: 0 | AT33: 7 | AU33: 0 | AV33: 0
X35: 1 | Y35: 1 | AT35: 7 | AU35: 7 | AV35: 7 | BD35: 1
A38: التعويضات العائلية | M38: 0.06
AT39: 7 | AU39: 7 | AV39: 7
AT41: 7 | AU41: 7 | AV41: 7
X43: 1 | Y43: 0 | AT43: 7 | AU43: 7 | AV43: 7 | BD43: 2
E44: مجموع الاشتراكات المستحقة
X46: 1 | Y46: 1
E47: التعويضات العائلية المدفوعة
A49: الزيادة المتوجبة على الصندوق/الباقي المتوجب للصندوق
AZ51: المصفي | BA51: ………...………
A53: ــــــــــــــــــــــــــــ في ـــــــــــــــــــــــ 20 | O53: توقيع وختم رب العمل | AZ53: المراقب | BA53: ………...………
A54: ملاحظة هامة: | AE54: مجموع المبالغ المدفوعة | AZ54: المحاسب | BA54: ………...………
A55: يتوجب اعادة هذا الجدول مع جدول التصريح الاسمي السنوي المرفق
BA56: cnss 351

Sheet الرواتب والاجور
A1: الضمان الاجتماعي
A2: التسوية السنوية
B3: 2025 | I3: 1
O5: فرع نهاية الخدمة (دون حد اقصى) | Q5: الاجور ضمن الحد الاقصى السنوي
A6: الرقم | B6: رقم المضمون | D6: مدرّس :0 | E6: الاسم والشهرة | F6: تاريخ بدء العمل | I6: تاريخ ترك العمل | L6: مدة العمل | N6: اجمالي الاجور | O6: اجمالي الاجور | P6: الاشتراكات | Q6: التعويضات | R6: المرض | S6: ملاحظات
D7: عامل:1 | F7: يوم | G7: شهر | H7: سنة | I7: يوم | J7: شهر | K7: سنة | L7: يوم | M7: شهر | N7: السنوية | O7: السنوية | P7: المتوجبة *8.5% | Q7: العائلية | R7: والامومة
A8: 1 | B8: 49814 | C8: 1948 | D8: 1 | E8: حنا لطف الله ابي عكر | F8: 1 | G8: 11 | H8: 2020 | I8: 30 | J8: 6 | K8: 2025 | L8: =IF($H8=0,0,IF($H8<$N$4,IF($K8=$N$4,IF($J8<10,$J8,9),9))+IF($H8=$N$4,IF($K8=$N$4,IF($J8<10,$J8-$G8+1,9-$G8+1))+IF($H8=$N$4,IF($K8=0,IF($G8<10,9-$G8+1,0),0)))) -> 0 | M8: 6 | N8: 110550000 | O8: 110550000 | P8: 9396750 | Q8: 72000000 | R8: 110550000
A9: =IF(R9=0,0,1) -> 1 | B9: 602992 | C9: 1962 | E9: عايده يوسف طنوس | F9: 1 | G9: 10 | H9: 2018 | I9: 30 | J9: 9 | K9: 2025 | L9: =IF($H9=0,0,IF($H9<$N$4,IF($K9=$N$4,IF($J9<10,$J9,9),9))+IF($H9=$N$4,IF($K9=$N$4,IF($J9<10,$J9-$G9+1,9-$G9+1))+IF($H9=$N$4,IF($K9=0,IF($G9<10,9-$G9+1,0),0)))) -> 0 | M9: 9 | N9: 182000000 | O9: 0 | P9: 0 | Q9: 0 | R9: 182000000
A10: =IF(R10=0,0,1) -> 1 | B10: 639852 | C10: 1960 | E10: رمون وديع روكس داموري | F10: 1 | G10: 2 | H10: 2017 | L10: =IF($H10=0,0,IF($H10<$N$4,IF($K10=$N$4,IF($J10<10,$J10,9),9))+IF($H10=$N$4,IF($K10=$N$4,IF($J10<10,$J10-$G10+1,9-$G10+1))+IF($H10=$N$4,IF($K10=0,IF($G10<10,9-$G10+1,0),0)))) -> 0 | M10: 12 | N10: 341075000 | O10: 0 | P10: 0 | Q10: 0 | R10: 341075000
A11: =IF(R11=0,0,1) -> 1 | B11: 726166 | C11: 1966 | E11: اسكندر منير عبود | F11: 1 | G11: 4 | H11: 2023 | L11: =IF($H11=0,0,IF($H11<$N$4,IF($K11=$N$4,IF($J11<10,$J11,9),9))+IF($H11=$N$4,IF($K11=$N$4,IF($J11<10,$J11-$G11+1,9-$G11+1))+IF($H11=$N$4,IF($K11=0,IF($G11<10,9-$G11+1,0),0)))) -> 0 | M11: 12 | N11: 278000000 | O11: 0 | P11: 0 | Q11: 0 | R11: 278000000
A12: =IF(R12=0,0,1) -> 1 | B12: 778170 | C12: 1965 | E12: اندريه يوسف مراد | F12: 1 | G12: 10 | H12: 2022 | L12: =IF($H12=0,0,IF($H12<$N$4,IF($K12=$N$4,IF($J12<10,$J12,9),9))+IF($H12=$N$4,IF($K12=$N$4,IF($J12<10,$J12-$G12+1,9-$G12+1))+IF($H12=$N$4,IF($K12=0,IF($G12<10,9-$G12+1,0),0)))) -> 0 | M12: 12 | N12: 353990000 | O12: 0 | P12: 0 | Q12: 0 | R12: 353990000
A13: =IF(R13=0,0,1) -> 1 | B13: 788049 | C13: 1967 | E13: ريتا خليل بو خليل | F13: 1 | G13: 10 | H13: 2010 | L13: =IF($H13=0,0,IF($H13<$N$4,IF($K13=$N$4,IF($J13<10,$J13,9),9))+IF($H13=$N$4,IF($K13=$N$4,IF($J13<10,$J13-$G13+1,9-$G13+1))+IF($H13=$N$4,IF($K13=0,IF($G13<10,9-$G13+1,0),0)))) -> 0 | M13: 12 | N13: 353645000 | O13: 0 | P13: 0 | Q13: 0 | R13: 353645000
A14: =IF(R14=0,0,1) -> 1 | B14: 788055 | C14: 1967 | E14: ميشلين جورج يونس | F14: 1 | G14: 10 | H14: 2025 | L14: =IF($H14=0,0,IF($H14<$N$4,IF($K14=$N$4,IF($J14<10,$J14,9),9))+IF($H14=$N$4,IF($K14=$N$4,IF($J14<10,$J14-$G14+1,9-$G14+1))+IF($H14=$N$4,IF($K14=0,IF($G14<10,9-$G14+1,0),0)))) -> 0 | M14: 12 | N14: 171300000 | O14: 0 | P14: 0 | Q14: 0 | R14: 171300000
A15: =IF(R15=0,0,1) -> 1 | B15: 7878093 | C15: 1964 | E15: طانيوس جرجس القزي | F15: 1 | G15: 10 | H15: 2024 | L15: =IF($H15=0,0,IF($H15<$N$4,IF($K15=$N$4,IF($J15<10,$J15,9),9))+IF($H15=$N$4,IF($K15=$N$4,IF($J15<10,$J15-$G15+1,9-$G15+1))+IF($H15=$N$4,IF($K15=0,IF($G15<10,9-$G15+1,0),0)))) -> 0 | M15: 12 | N15: 280000000 | O15: 0 | P15: 0 | Q15: 0 | R15: 280000000
A16: =IF(R16=0,0,1) -> 1 | B16: 911695 | C16: 1975 | D16: 1 | E16: انطوان جورج دايخ | F16: 1 | G16: 10 | H16: 2019 | L16: =IF($H16=0,0,IF($H16<$N$4,IF($K16=$N$4,IF($J16<10,$J16,9),9))+IF($H16=$N$4,IF($K16=$N$4,IF($J16<10,$J16-$G16+1,9-$G16+1))+IF($H16=$N$4,IF($K16=0,IF($G16<10,9-$G16+1,0),0)))) -> 0 | M16: 12 | N16: 277675000 | O16: 277675000 | P16: 23602375 | Q16: 180000000 | R16: 277675000
A17: =IF(R17=0,0,1) -> 1 | B17: 931375 | C17: 1969 | E17: دنيا جرجس القزي | F17: 1 | G17: 10 | H17: 2010 | L17: =IF($H17=0,0,IF($H17<$N$4,IF($K17=$N$4,IF($J17<10,$J17,9),9))+IF($H17=$N$4,IF($K17=$N$4,IF($J17<10,$J17-$G17+1,9-$G17+1))+IF($H17=$N$4,IF($K17=0,IF($G17<10,9-$G17+1,0),0)))) -> 0 | M17: 12 | N17: 353015000 | O17: 0 | P17: 0 | Q17: 0 | R17: 353015000
A18: =IF(R18=0,0,1) -> 1 | B18: 943989 | C18: 1966 | E18: ندى ميلاد ابو خليل | F18: 1 | G18: 10 | H18: 2010 | L18: =IF($H18=0,0,IF($H18<$N$4,IF($K18=$N$4,IF($J18<10,$J18,9),9))+IF($H18=$N$4,IF($K18=$N$4,IF($J18<10,$J18-$G18+1,9-$G18+1))+IF($H18=$N$4,IF($K18=0,IF($G18<10,9-$G18+1,0),0)))) -> 0 | M18: 12 | N18: 341075000 | O18: 0 | P18: 0 | Q18: 0 | R18: 341075000
A19: =IF(R19=0,0,1) -> 1 | B19: 980121 | C19: 1972 | E19: الين فكتور ناكوزي | F19: 1 | G19: 10 | H19: 2022 | I19: 30 | J19: 9 | K19: 2025 | L19: =IF($H19=0,0,IF($H19<$N$4,IF($K19=$N$4,IF($J19<10,$J19,9),9))+IF($H19=$N$4,IF($K19=$N$4,IF($J19<10,$J19-$G19+1,9-$G19+1))+IF($H19=$N$4,IF($K19=0,IF($G19<10,9-$G19+1,0),0)))) -> 0 | M19: 9 | N19: 182000000 | O19: 0 | P19: 0 | Q19: 0 | R19: 182000000
A20: =IF(R20=0,0,1) -> 1 | B20: 1006749 | C20: 1960 | E20: ليلى جرجس قمير | F20: 1 | G20: 10 | H20: 2010 | L20: =IF($H20=0,0,IF($H20<$N$4,IF($K20=$N$4,IF($J20<10,$J20,9),9))+IF($H20=$N$4,IF($K20=$N$4,IF($J20<10,$J20-$G20+1,9-$G20+1))+IF($H20=$N$4,IF($K20=0,IF($G20<10,9-$G20+1,0),0)))) -> 0 | M20: 12 | N20: 341000000 | O20: 0 | P20: 0 | Q20: 0 | R20: 341000000
A21: =IF(R21=0,0,1) -> 1 | B21: 1031591 | C21: 1976 | E21: ريما كرم الكركي | F21: 1 | G21: 10 | H21: 2010 | L21: =IF($H21=0,0,IF($H21<$N$4,IF($K21=$N$4,IF($J21<10,$J21,9),9))+IF($H21=$N$4,IF($K21=$N$4,IF($J21<10,$J21-$G21+1,9-$G21+1))+IF($H21=$N$4,IF($K21=0,IF($G21<10,9-$G21+1,0),0)))) -> 0 | M21: 12 | N21: 355805000 | O21: 0 | P21: 0 | Q21: 0 | R21: 355805000
A22: =IF(R22=0,0,1) -> 1 | B22: 1033307 | C22: 1964 | E22: زاهيه اميل الحاج | F22: 1 | G22: 10 | H22: 2010 | L22: =IF($H22=0,0,IF($H22<$N$4,IF($K22=$N$4,IF($J22<10,$J22,9),9))+IF($H22=$N$4,IF($K22=$N$4,IF($J22<10,$J22-$G22+1,9-$G22+1))+IF($H22=$N$4,IF($K22=0,IF($G22<10,9-$G22+1,0),0)))) -> 0 | M22: 12 | N22: 356585000 | O22: 0 | P22: 0 | Q22: 0 | R22: 356585000
A23: =IF(R23=0,0,1) -> 1 | B23: 1222516 | C23: 1984 | E23: الين شربل منصور | F23: 1 | G23: 10 | H23: 2010 | L23: =IF($H23=0,0,IF($H23<$N$4,IF($K23=$N$4,IF($J23<10,$J23,9),9))+IF($H23=$N$4,IF($K23=$N$4,IF($J23<10,$J23-$G23+1,9-$G23+1))+IF($H23=$N$4,IF($K23=0,IF($G23<10,9-$G23+1,0),0)))) -> 0 | M23: 12 | N23: 354335000 | O23: 0 | P23: 0 | Q23: 0 | R23: 354335000
A24: =IF(R24=0,0,1) -> 1 | B24: 1239319 | C24: 1982 | E24: دنيا شاهين فلفلي | F24: 1 | G24: 10 | H24: 2010 | L24: =IF($H24=0,0,IF($H24<$N$4,IF($K24=$N$4,IF($J24<10,$J24,9),9))+IF($H24=$N$4,IF($K24=$N$4,IF($J24<10,$J24-$G24+1,9-$G24+1))+IF($H24=$N$4,IF($K24=0,IF($G24<10,9-$G24+1,0),0)))) -> 0 | M24: 12 | N24: 352160000 | O24: 0 | P24: 0 | Q24: 0 | R24: 352160000
A25: =IF(R25=0,0,1) -> 1 | B25: 1261791 | C25: 1981 | E25: رامونا ريمون الاسمر | F25: 1 | G25: 10 | H25: 2015 | L25: =IF($H25=0,0,IF($H25<$N$4,IF($K25=$N$4,IF($J25<10,$J25,9),9))+IF($H25=$N$4,IF($K25=$N$4,IF($J25<10,$J25-$G25+1,9-$G25+1))+IF($H25=$N$4,IF($K25=0,IF($G25<10,9-$G25+1,0),0)))) -> 0 | M25: 12 | N25: 349445000 | O25: 0 | P25: 0 | Q25: 0 | R25: 349445000
A26: =IF(R26=0,0,1) -> 1 | B26: 1265691 | C26: 1978 | E26: شربل انطوان راجحة | F26: 1 | G26: 10 | H26: 2021 | L26: =IF($H26=0,0,IF($H26<$N$4,IF($K26=$N$4,IF($J26<10,$J26,9),9))+IF($H26=$N$4,IF($K26=$N$4,IF($J26<10,$J26-$G26+1,9-$G26+1))+IF($H26=$N$4,IF($K26=0,IF($G26<10,9-$G26+1,0),0)))) -> 0 | M26: 12 | N26: 354680000 | O26: 0 | P26: 0 | Q26: 0 | R26: 354680000
A27: =SUM(A8:A26) -> 19 | D27: =SUM(D8:D26) -> 2 | E27: المجموع | F27: =SUM(F8:F26) -> 19 | G27: =SUM(G8:G26) -> 177 | H27: =SUM(H8:H26) -> 38306 | I27: =SUM(I8:I26) -> 90 | J27: =SUM(J8:J26) -> 24 | K27: =SUM(K8:K26) -> 6075 | L27: =SUM(L8:L26) -> 0 | M27: =SUM(M8:M26) -> 216 | ... R27: =SUM(R8:R26) -> 5688335000
A28: =IF(R28=0,0,1) -> 1 | B28: 1270067 | C28: 1967 | E28: انطوان ديب الحاج | F28: 1 | G28: 10 | H28: 2010 | L28: =IF($H28=0,0,IF($H28<$N$4,IF($K28=$N$4,IF($J28<10,$J28,9),9))+IF($H28=$N$4,IF($K28=$N$4,IF($J28<10,$J28-$G28+1,9-$G28+1))+IF($H28=$N$4,IF($K28=0,IF($G28<10,9-$G28+1,0),0)))) -> 0 | M28: 12 | N28: 352160000 | O28: 0 | P28: 0 | Q28: 0 | R28: 352160000
A29: =IF(R29=0,0,1) -> 1 | B29: 1308770 | C29: 1986 | E29: فادي ريمون المدور | F29: 1 | G29: 3 | H29: 2024 | L29: =IF($H29=0,0,IF($H29<$N$4,IF($K29=$N$4,IF($J29<10,$J29,9),9))+IF($H29=$N$4,IF($K29=$N$4,IF($J29<10,$J29-$G29+1,9-$G29+1))+IF($H29=$N$4,IF($K29=0,IF($G29<10,9-$G29+1,0),0)))) -> 0 | M29: 12 | N29: 352160000 | O29: 0 | P29: 0 | Q29: 0 | R29: 352160000
A30: =IF(R30=0,0,1) -> 1 | B30: 1390558 | C30: 1987 | E30: غيتا جريس العلم | F30: 1 | G30: 10 | H30: 2020 | L30: =IF($H30=0,0,IF($H30<$N$4,IF($K30=$N$4,IF($J30<10,$J30,9),9))+IF($H30=$N$4,IF($K30=$N$4,IF($J30<10,$J30-$G30+1,9-$G30+1))+IF($H30=$N$4,IF($K30=0,IF($G30<10,9-$G30+1,0),0)))) -> 0 | M30: 12 | N30: 352160000 | O30: 0 | P30: 0 | Q30: 0 | R30: 352160000
A31: =IF(R31=0,0,1) -> 1 | B31: 1482294 | C31: 1992 | E31: نتالي شربل قنصل | F31: 1 | G31: 10 | H31: 2011 | I31: 30 | J31: 9 | K31: 2025 | L31: =IF($H31=0,0,IF($H31<$N$4,IF($K31=$N$4,IF($J31<10,$J31,9),9))+IF($H31=$N$4,IF($K31=$N$4,IF($J31<10,$J31-$G31+1,9-$G31+1))+IF($H31=$N$4,IF($K31=0,IF($G31<10,9-$G31+1,0),0)))) -> 0 | M31: 9 | N31: 182000000 | O31: 0 | P31: 0 | Q31: 0 | R31: 182000000
A32: =IF(R32=0,0,1) -> 1 | B32: 1537976 | C32: 1986 | E32: برنار رزق الله زغيب | F32: 1 | G32: 10 | H32: 2025 | L32: =IF($H32=0,0,IF($H32<$N$4,IF($K32=$N$4,IF($J32<10,$J32,9),9))+IF($H32=$N$4,IF($K32=$N$4,IF($J32<10,$J32-$G32+1,9-$G32+1))+IF($H32=$N$4,IF($K32=0,IF($G32<10,9-$G32+1,0),0)))) -> 0 | M32: 12 | N32: 166575000 | O32: 0 | P32: 0 | Q32: 0 | R32: 166575000
A33: =IF(R33=0,0,1) -> 1 | B33: 1571736 | C33: 1992 | E33: كريستينا بشاره مهاوج | F33: 1 | G33: 10 | H33: 2021 | I33: 30 | J33: 9 | K33: 2025 | L33: =IF($H33=0,0,IF($H33<$N$4,IF($K33=$N$4,IF($J33<10,$J33,9),9))+IF($H33=$N$4,IF($K33=$N$4,IF($J33<10,$J33-$G33+1,9-$G33+1))+IF($H33=$N$4,IF($K33=0,IF($G33<10,9-$G33+1,0),0)))) -> 0 | M33: 9 | N33: 182000000 | O33: 0 | P33: 0 | Q33: 0 | R33: 182000000
A34: =IF(R34=0,0,1) -> 1 | B34: 1579181 | C34: 1989 | E34: كريستل ميشال الشختوره | F34: 1 | G34: 10 | H34: 2016 | L34: =IF($H34=0,0,IF($H34<$N$4,IF($K34=$N$4,IF($J34<10,$J34,9),9))+IF($H34=$N$4,IF($K34=$N$4,IF($J34<10,$J34-$G34+1,9-$G34+1))+IF($H34=$N$4,IF($K34=0,IF($G34<10,9-$G34+1,0),0)))) -> 0 | M34: 12 | N34: 351395000 | O34: 0 | P34: 0 | Q34: 0 | R34: 351395000
A35: =IF(R35=0,0,1) -> 1 | B35: 1619057 | C35: 1990 | E35: راف بيار عاصي | F35: 1 | G35: 10 | H35: 2021 | I35: 30 | J35: 9 | K35: 2025 | L35: =IF($H35=0,0,IF($H35<$N$4,IF($K35=$N$4,IF($J35<10,$J35,9),9))+IF($H35=$N$4,IF($K35=$N$4,IF($J35<10,$J35-$G35+1,9-$G35+1))+IF($H35=$N$4,IF($K35=0,IF($G35<10,9-$G35+1,0),0)))) -> 0 | M35: 9 | N35: 182000000 | O35: 0 | P35: 0 | Q35: 0 | R35: 182000000
A36: =IF(R36=0,0,1) -> 1 | B36: 1718010 | C36: 1992 | E36: جيما ريمون عبود | F36: 1 | G36: 10 | H36: 2023 | L36: =IF($H36=0,0,IF($H36<$N$4,IF($K36=$N$4,IF($J36<10,$J36,9),9))+IF($H36=$N$4,IF($K36=$N$4,IF($J36<10,$J36-$G36+1,9-$G36+1))+IF($H36=$N$4,IF($K36=0,IF($G36<10,9-$G36+1,0),0)))) -> 0 | M36: 12 | N36: 347495000 | O36: 0 | P36: 0 | Q36: 0 | R36: 347495000
A37: =IF(R37=0,0,1) -> 1 | B37: 1820741 | C37: 1996 | E37: برلا انطوان نمور | F37: 1 | G37: 10 | H37: 2018 | L37: =IF($H37=0,0,IF($H37<$N$4,IF($K37=$N$4,IF($J37<10,$J37,9),9))+IF($H37=$N$4,IF($K37=$N$4,IF($J37<10,$J37-$G37+1,9-$G37+1))+IF($H37=$N$4,IF($K37=0,IF($G37<10,9-$G37+1,0),0)))) -> 0 | M37: 12 | N37: 350915000 | O37: 0 | P37: 0 | Q37: 0 | R37: 350915000
A38: =IF(R38=0,0,1) -> 1 | B38: 1827099 | C38: 1971 | E38: خطار خليل معلوف | F38: 1 | G38: 10 | H38: 2018 | L38: =IF($H38=0,0,IF($H38<$N$4,IF($K38=$N$4,IF($J38<10,$J38,9),9))+IF($H38=$N$4,IF($K38=$N$4,IF($J38<10,$J38-$G38+1,9-$G38+1))+IF($H38=$N$4,IF($K38=0,IF($G38<10,9-$G38+1,0),0)))) -> 0 | M38: 12 | N38: 281075000 | O38: 0 | P38: 0 | Q38: 0 | R38: 281075000
A39: =IF(R39=0,0,1) -> 1 | B39: 1900939 | C39: 1997 | E39: ريتا انطوان بجاني | F39: 1 | G39: 10 | H39: 2024 | L39: =IF($H39=0,0,IF($H39<$N$4,IF($K39=$N$4,IF($J39<10,$J39,9),9))+IF($H39=$N$4,IF($K39=$N$4,IF($J39<10,$J39-$G39+1,9-$G39+1))+IF($H39=$N$4,IF($K39=0,IF($G39<10,9-$G39+1,0),0)))) -> 0 | M39: 12 | N39: 306575000 | O39: 0 | P39: 0 | Q39: 0 | R39: 306575000
A40: =IF(R40=0,0,1) -> 1 | B40: 1924226 | C40: 1999 | E40: مارسيلا جورج داود | F40: 1 | G40: 10 | H40: 2021 | L40: =IF($H40=0,0,IF($H40<$N$4,IF($K40=$N$4,IF($J40<10,$J40,9),9))+IF($H40=$N$4,IF($K40=$N$4,IF($J40<10,$J40-$G40+1,9-$G40+1))+IF($H40=$N$4,IF($K40=0,IF($G40<10,9-$G40+1,0),0)))) -> 0 | M40: 12 | N40: 349445000 | O40: 0 | P40: 0 | Q40: 0 | R40: 349445000
A41: =IF(R41=0,0,1) -> 1 | B41: 1924232 | C41: 1999 | E41: مارغريتا مارون بو نصار | F41: 1 | G41: 10 | H41: 2021 | L41: =IF($H41=0,0,IF($H41<$N$4,IF($K41=$N$4,IF($J41<10,$J41,9),9))+IF($H41=$N$4,IF($K41=$N$4,IF($J41<10,$J41-$G41+1,9-$G41+1))+IF($H41=$N$4,IF($K41=0,IF($G41<10,9-$G41+1,0),0)))) -> 0 | M41: 12 | N41: 350255000 | O41: 0 | P41: 0 | Q41: 0 | R41: 350255000
...

Sheet التصريح الاسمي 
A2: الصندوق الوطني | D2: الرقم | E2: ='الرواتب والاجور'!M2 -> 0 | F2: 82 | G2: ='الرواتب والاجور'!P2 -> 0
A3: للضمان الاجتماعي
A4: التصريح الاسمي | C4: جانب صاحب العمل | D4: ='الرواتب والاجور'!#REF! -> #REF!
A5: لسنة : | B5: ='الرواتب والاجور'!B3 -> 2025
B6: بناء على المادة 80 (من فقرة5) من قانون الضمان الاجتماعي المعدل بموجب المرسوم الاشتراعي رقم 73/116
B7: وبناء على نظام الاشتراكات لدى الصندوق
B8: ندعوكم الى كشف المعلومات المطلوبة ادناه واعادة هذا التصريح والجدول الملحق به مع المعلومات المطلوبة ودفع
B9: الرصيد المتوجب خلال مهلة اقصاها 31 اذار
A10: (أ) | B10: مراجعة الاجور التي دفعت عنها الاشتراكات خلال السنة:
C11: المدة | D11: فرع نهاية الخدمة | E11: فرع التعويضات العائلية | F11: فرع المرض والامومة
C12: كانون الثاني | D12: 18525000 | E12: 24000000 | F12: 630950000
C13: شباط | D13: 18525000 | E13: 24000000 | F13: 630950000
C14: اذار | D14: 18525000 | E14: 24000000 | F14: 630950000
C15: نيسان | D15: 18525000 | E15: 24000000 | F15: 630950000
C16: ايار | D16: 18525000 | E16: 24000000 | F16: 630950000
C17: حزيران | D17: 18525000 | E17: 24000000 | F17: 630950000
C18: تموز | D18: 18525000 | E18: 18000000 | F18: 594525000
C19: اب | D19: 29000000 | E19: 18000000 | F19: 926000000
C20: ايلول | D20: 29000000 | E20: 18000000 | F20: 926000000
A21: المصفي : | B21: ............................... | C21: تشرين الاول | D21: 30000000 | E21: 18000000 | F21: 1505320000
A22: المراقب : | B22: ............................... | C22: تشرين الثاني | D22: 30000000 | E22: 18000000 | F22: 1505320000
A23: المحاسب : | B23: ............................... | C23: كانون الاول | D23: 30000000 | E23: 18000000 | F23: 1505320000
C24: فروقات | D24: 0 | E24: 0 | F24: 0
C25: المجاميع | D25: =SUM(D12:D24) -> 277675000 | E25: =SUM(E12:E24) -> 252000000 | F25: =SUM(F12:F24) -> 10748185000
D26: (حقل 1) | E26: (حقل 2) | F26: (حقل 3)
A27: (ب) | B27: اشتراكات التسوية السنوية المتوجب تسديدها
D28: فرع نهاية الخدمة | E28: فرع التعويضات العائلية | F28: فرع المرض والامومة
B29: مجموع الاجور وفقا للجدول الملحق بهذا التصريح | D29: ='الرواتب والاجور'!O68 -> 388225000 | E29: ='الرواتب والاجور'!Q68 -> 252000000 | F29: ='الرواتب والاجور'!R68 -> 10748185000
B30: ناقص | D30: (حقل 4) | E30: (حقل 5) | F30: (حقل 6)
B31: مجموع الاجور كما هو مبين في الحقل (أ) اعلاه | D31: =D25 -> 277675000 | E31: =E25 -> 252000000 | F31: =F25 -> 10748185000
D32: (حقل 1) | E32: (حقل 2) | F32: (حقل 3)
B33: يساوي | D33: =D29-D31 -> 110550000 | E33: =E29-E31 -> 0 | F33: =F29-F31 -> 0
D34: 0.085 | E34: 0.06 | F34: 0.11
B35: اجور التسوية | D35: =D33*D34 -> 9396750 | E35: =E33*E34 -> 0 | F35: =F33*F34 -> 0
C36: مجموع اشتراكات التسوية المتوجب دفعها | E36: =F35+E35+D35 -> 9396750
A37: (ج) | B37: مطبوعة ملحقة بالتصريح الاسمي السنوي
B38: انا الموقع ادناه : | E38: بصفتي : | F38: مسؤولة عن الضمان الاجتماعي
B39: اشهد ان جميع المعلومات التي اعطيتها على هذا التصريح والجدول الملحق به ، مطابقة للحقيقة بعد اجراء جميع التصحيحات
B40: والتعديلات والاضافات اللازمة على الجدول الملحق المذكور.
D41: في :
...
